(dp1
S'output'
p2
S"<type 'exceptions.KeyError'> "
p3
sS'layer'
p4
S'/home/abdulhalim/Desktop/web2py/applications/motor/controllers/default.py'
p5
sS'code'
p6
S'<code object <module> at 0x7f8ad6ad1f30, file "/home/abdulhalim/Desktop/web2py/applications/motor/controllers/default.py", line 1>'
p7
sS'snapshot'
p8
(dp9
sS'traceback'
p10
S'Traceback (most recent call last):\n  File "/home/abdulhalim/Desktop/web2py/gluon/restricted.py", line 219, in restricted\n    exec(ccode, environment)\n  File "/home/abdulhalim/Desktop/web2py/applications/motor/controllers/default.py", line 65, in <module>\n  File "/home/abdulhalim/Desktop/web2py/gluon/globals.py", line 409, in <lambda>\n    self._caller = lambda f: f()\n  File "/home/abdulhalim/Desktop/web2py/gluon/tools.py", line 3964, in f\n    return action(*a, **b)\n  File "/home/abdulhalim/Desktop/web2py/applications/motor/controllers/default.py", line 9, in add_device\n    user_name = "%(username)s" % auth.user\n  File "/home/abdulhalim/Desktop/web2py/gluon/packages/dal/pydal/objects.py", line 84, in __getitem__\n    raise KeyError\nKeyError\n'
p11
s.