(dp1
S'output'
p2
S'<type \'exceptions.RuntimeError\'> Failure to connect, tried 5 times:\nTraceback (most recent call last):\n  File "/home/abdulhalim/Desktop/web2py/gluon/packages/dal/pydal/base.py", line 455, in __init__\n    self._adapter = adapter(**kwargs)\n  File "/home/abdulhalim/Desktop/web2py/gluon/packages/dal/pydal/adapters/__init__.py", line 40, in __call__\n    obj = super(AdapterMeta, cls).__call__(*args, **kwargs)\n  File "/home/abdulhalim/Desktop/web2py/gluon/packages/dal/pydal/adapters/base.py", line 367, in __init__\n    super(SQLAdapter, self).__init__(*args, **kwargs)\n  File "/home/abdulhalim/Desktop/web2py/gluon/packages/dal/pydal/adapters/base.py", line 52, in __init__\n    self.reconnect()\n  File "/home/abdulhalim/Desktop/web2py/gluon/packages/dal/pydal/connection.py", line 152, in reconnect\n    self.connection = self.connector()\n  File "/home/abdulhalim/Desktop/web2py/gluon/packages/dal/pydal/adapters/mysql.py", line 52, in connector\n    return self.driver.connect(**self.driver_args)\n  File "/home/abdulhalim/Desktop/web2py/gluon/contrib/pymysql/__init__.py", line 90, in Connect\n    return Connection(*args, **kwargs)\n  File "/home/abdulhalim/Desktop/web2py/gluon/contrib/pymysql/connections.py", line 688, in __init__\n    self.connect()\n  File "/home/abdulhalim/Desktop/web2py/gluon/contrib/pymysql/connections.py", line 937, in connect\n    raise exc\nOperationalError: (2003, "Can\'t connect to MySQL server on \'localhost\' ([Errno 111] Connection refused)")\n'
p3
sS'layer'
p4
S'/home/abdulhalim/Desktop/web2py/applications/motor/models/db.py'
p5
sS'code'
p6
S'<code object <module> at 0x7f8da81bb430, file "/home/abdulhalim/Desktop/web2py/applications/motor/models/db.py", line 8>'
p7
sS'snapshot'
p8
(dp9
sS'traceback'
p10
S'Traceback (most recent call last):\n  File "/home/abdulhalim/Desktop/web2py/gluon/restricted.py", line 219, in restricted\n    exec(ccode, environment)\n  File "/home/abdulhalim/Desktop/web2py/applications/motor/models/db.py", line 37, in <module>\n    db = DAL(\'mysql://root:*Cantaccessme7*@localhost/motor\')\n  File "/home/abdulhalim/Desktop/web2py/gluon/packages/dal/pydal/base.py", line 170, in __call__\n    obj = super(MetaDAL, cls).__call__(*args, **kwargs)\n  File "/home/abdulhalim/Desktop/web2py/gluon/packages/dal/pydal/base.py", line 475, in __init__\n    "Failure to connect, tried %d times:\\n%s" % (attempts, tb)\nRuntimeError: Failure to connect, tried 5 times:\nTraceback (most recent call last):\n  File "/home/abdulhalim/Desktop/web2py/gluon/packages/dal/pydal/base.py", line 455, in __init__\n    self._adapter = adapter(**kwargs)\n  File "/home/abdulhalim/Desktop/web2py/gluon/packages/dal/pydal/adapters/__init__.py", line 40, in __call__\n    obj = super(AdapterMeta, cls).__call__(*args, **kwargs)\n  File "/home/abdulhalim/Desktop/web2py/gluon/packages/dal/pydal/adapters/base.py", line 367, in __init__\n    super(SQLAdapter, self).__init__(*args, **kwargs)\n  File "/home/abdulhalim/Desktop/web2py/gluon/packages/dal/pydal/adapters/base.py", line 52, in __init__\n    self.reconnect()\n  File "/home/abdulhalim/Desktop/web2py/gluon/packages/dal/pydal/connection.py", line 152, in reconnect\n    self.connection = self.connector()\n  File "/home/abdulhalim/Desktop/web2py/gluon/packages/dal/pydal/adapters/mysql.py", line 52, in connector\n    return self.driver.connect(**self.driver_args)\n  File "/home/abdulhalim/Desktop/web2py/gluon/contrib/pymysql/__init__.py", line 90, in Connect\n    return Connection(*args, **kwargs)\n  File "/home/abdulhalim/Desktop/web2py/gluon/contrib/pymysql/connections.py", line 688, in __init__\n    self.connect()\n  File "/home/abdulhalim/Desktop/web2py/gluon/contrib/pymysql/connections.py", line 937, in connect\n    raise exc\nOperationalError: (2003, "Can\'t connect to MySQL server on \'localhost\' ([Errno 111] Connection refused)")\n\n'
p11
s.